<?xml version='1.0' encoding='UTF-8'?>
<robot xmlns:xacro="http://ros.org/wiki/xacro" name="griphis_xacro_stl"><xacro:macro name="griphis_xacro_stl" params="prefix parent_link *origin">
        <joint name="${prefix}gripper-cp1_to_${parent_link}_joint" type="fixed">
            <parent link="${parent_link}"/>
            <child link="${prefix}gripper-cp1"/>
            <xacro:insert_block name="origin"/>
            </joint>
        <link name="${prefix}base_link">
            <inertial>
                <origin xyz="-0.00010264257406678 3.31727350517397E-05 -0.00495518296571391" rpy="0 0 0"/>
                <mass value="0.0797462541060097"/>
                <inertia ixx="8.57012114371153E-06" ixy="1.08293491537705E-08" ixz="-5.94275788505759E-09" iyy="1.05158543807875E-05" iyz="1.10583333432373E-08" izz="1.08869595154247E-05"/>
                </inertial>
            <visual>
                <origin xyz="-0.0148999999999995 0.0176000000000318 0.0109999999999849" rpy="0.0 -0.0 0.0"/>
                <geometry>
                    <mesh filename="package://griphis_xacro_stl/meshes/base_link.STL"/>
                    </geometry>
                <material name="">
                    <color rgba="0.752941176470588 0.752941176470588 0.752941176470588 1"/>
                    </material>
                </visual>
            <collision>
                <origin xyz="-0.0148999999999995 0.0176000000000318 0.0109999999999849" rpy="0.0 -0.0 0.0"/>
                <geometry>
                    <mesh filename="package://griphis_xacro_stl/meshes/base_link.STL"/>
                    </geometry>
                </collision>
            </link>
        <link name="${prefix}mid_pitch_1_link">
            <inertial>
                <origin xyz="0.0327517154872403 0.0322634011493343 0.000309410745622088" rpy="0 0 0"/>
                <mass value="0.0769353285466722"/>
                <inertia ixx="1.72122749770761E-05" ixy="1.01496940835006E-08" ixz="-9.64331189423188E-08" iyy="1.36641198773196E-05" iyz="5.60814889063421E-07" izz="1.63211688368785E-05"/>
                </inertial>
            <visual>
                <origin xyz="-0.0640000000000069 -0.0350999999999983 -0.0" rpy="0.0 -0.0 0.0"/>
                <geometry>
                    <mesh filename="package://griphis_xacro_stl/meshes/mid_pitch_1_link.STL"/>
                    </geometry>
                <material name="">
                    <color rgba="0.752941176470588 0.752941176470588 0.752941176470588 1"/>
                    </material>
                </visual>
            <collision>
                <origin xyz="-0.0640000000000069 -0.0350999999999983 -0.0" rpy="0.0 -0.0 0.0"/>
                <geometry>
                    <mesh filename="package://griphis_xacro_stl/meshes/mid_pitch_1_link.STL"/>
                    </geometry>
                </collision>
            </link>
        <joint name="${prefix}mid_pitch_1" type="continuous">
            <origin xyz="-0.0640000000000069 -0.0350999999999983 -0.0" rpy="0.0 -0.0 0.0"/>
            <parent link="${prefix}mid_pitch_1_link"/>
            <child link="${prefix}base_link"/>
            <axis xyz="-0.0 -1.0 -0.0"/>
            <limit effort="3" velocity="10"/>
            </joint>
        <link name="${prefix}pitch_1_link">
            <inertial>
                <origin xyz="0.0191893034316777 -0.017231596070573 -0.00342856576321433" rpy="0 0 0"/>
                <mass value="0.0105178263834885"/>
                <inertia ixx="5.84801171286377E-07" ixy="3.57321505354626E-09" ixz="8.8152444778668E-08" iyy="1.04603360596441E-06" iyz="-1.51990885783075E-13" izz="9.82964870358909E-07"/>
                </inertial>
            <visual>
                <origin xyz="-0.0420000000000015 0.0175000000000007 -0.0174999999999981" rpy="0.0 -0.0 0.0"/>
                <geometry>
                    <mesh filename="package://griphis_xacro_stl/meshes/pitch_1_link.STL"/>
                    </geometry>
                <material name="">
                    <color rgba="0.298039215686275 0.298039215686275 0.298039215686275 1"/>
                    </material>
                </visual>
            <collision>
                <origin xyz="-0.0420000000000015 0.0175000000000007 -0.0174999999999981" rpy="0.0 -0.0 0.0"/>
                <geometry>
                    <mesh filename="package://griphis_xacro_stl/meshes/pitch_1_link.STL"/>
                    </geometry>
                </collision>
            </link>
        <joint name="${prefix}pitch_1" type="continuous">
            <origin xyz="-0.0420000000000015 0.0175000000000007 -0.0174999999999981" rpy="0.0 -0.0 0.0"/>
            <parent link="${prefix}pitch_1_link"/>
            <child link="${prefix}mid_pitch_1_link"/>
            <axis xyz="-0.0 -1.0 -0.0"/>
            <limit effort="3" velocity="10"/>
            </joint>
        <link name="${prefix}yaw_1_link">
            <inertial>
                <origin xyz="0.00934924439107056 -1.17000596711048E-10 -0.0065657034112081" rpy="0 0 0"/>
                <mass value="0.0544535701857151"/>
                <inertia ixx="6.16082295678474E-06" ixy="-1.48642619322733E-08" ixz="3.66332313625793E-08" iyy="7.36782974228272E-06" iyz="-1.48634431569832E-08" izz="7.24406343523596E-06"/>
                </inertial>
            <visual>
                <origin xyz="-0.0279999999999981 -0.0 0.0175000000000002" rpy="0.0 -0.0 0.0"/>
                <geometry>
                    <mesh filename="package://griphis_xacro_stl/meshes/yaw_1_link.STL"/>
                    </geometry>
                <material name="">
                    <color rgba="0.180392156862745 0.180392156862745 0.180392156862745 1"/>
                    </material>
                </visual>
            <collision>
                <origin xyz="-0.0279999999999981 -0.0 0.0175000000000002" rpy="0.0 -0.0 0.0"/>
                <geometry>
                    <mesh filename="package://griphis_xacro_stl/meshes/yaw_1_link.STL"/>
                    </geometry>
                </collision>
            </link>
        <joint name="${prefix}yaw_1" type="continuous">
            <origin xyz="-0.0279999999999981 -0.0 0.0175000000000002" rpy="0.0 -0.0 0.0"/>
            <parent link="${prefix}yaw_1_link"/>
            <child link="${prefix}pitch_1_link"/>
            <axis xyz="-0.0 -0.0 1.0"/>
            <limit effort="3" velocity="10"/>
            </joint>
        <link name="${prefix}roll_1_link">
            <inertial>
                <origin xyz="0.0304847934275313 -0.000533683595524997 -0.000138763582684304" rpy="0 0 0"/>
                <mass value="0.0617238803473503"/>
                <inertia ixx="1.72112591146286E-05" ixy="-2.34655399562005E-07" ixz="1.72186999812855E-07" iyy="1.09105230206178E-05" iyz="3.90599560040266E-08" izz="1.62402505711448E-05"/>
                </inertial>
            <visual>
                <origin xyz="-0.00031819805152675406 0.000318198051528346 -0.0766999999999999" rpy="0.0 -1.5707963267948966 -1.5707963267948966"/>
                <geometry>
                    <mesh filename="package://griphis_xacro_stl/meshes/roll_1_link.STL"/>
                    </geometry>
                <material name="">
                    <color rgba="1 1 1 1"/>
                    </material>
                </visual>
            <collision>
                <origin xyz="-0.00031819805152675406 0.000318198051528346 -0.0766999999999999" rpy="0.0 -1.5707963267948966 -1.5707963267948966"/>
                <geometry>
                    <mesh filename="package://griphis_xacro_stl/meshes/roll_1_link.STL"/>
                    </geometry>
                </collision>
            </link>
        <joint name="${prefix}roll_1" type="continuous">
            <origin xyz="-0.00031819805152675406 0.000318198051528346 -0.0766999999999999" rpy="0.0 -1.5707963267948966 -1.5707963267948966"/>
            <parent link="${prefix}roll_1_link"/>
            <child link="${prefix}yaw_1_link"/>
            <axis xyz="1.0 -0.0 -0.0"/>
            <limit effort="3" velocity="10"/>
            </joint>
        <link name="${prefix}worm_1_link">
            <inertial>
                <origin xyz="0.00680389923417661 1.29536242400655E-05 5.52986221441856E-05" rpy="0 0 0"/>
                <mass value="0.00387257618784269"/>
                <inertia ixx="2.06264558567859E-07" ixy="1.13917098659222E-09" ixz="-8.28881114232565E-10" iyy="1.7113732321225E-07" iyz="4.18404893657738E-11" izz="1.71297030362022E-07"/>
                </inertial>
            <visual>
                <origin xyz="0 0 0" rpy="0 0 0"/>
                <geometry>
                    <mesh filename="package://griphis_xacro_stl/meshes/worm_1_link.STL"/>
                    </geometry>
                <material name="">
                    <color rgba="0.752941176470588 0.752941176470588 0.752941176470588 1"/>
                    </material>
                </visual>
            <collision>
                <origin xyz="0 0 0" rpy="0 0 0"/>
                <geometry>
                    <mesh filename="package://griphis_xacro_stl/meshes/worm_1_link.STL"/>
                    </geometry>
                </collision>
            </link>
        <joint name="${prefix}worm_rotate_1" type="continuous">
            <origin xyz="-0.00031819805152675406 0.00031819805152833553 -0.02969999999999999" rpy="-1.5707963267948963 -1.5707963267948966 0.0"/>
            <parent link="${prefix}roll_1_link"/>
            <child link="${prefix}worm_1_link"/>
            <axis xyz="1 0 0"/>
            <limit effort="15" velocity="10"/>
            </joint>
        <link name="${prefix}nail1_1_link">
            <inertial>
                <origin xyz="0.0375115559402243 -4.52381021421033E-05 0.000927613439051046" rpy="0 0 0"/>
                <mass value="0.00785451508753953"/>
                <inertia ixx="3.26792929870295E-07" ixy="2.23311778369799E-10" ixz="3.04391588566406E-07" iyy="1.76174668735888E-06" iyz="-8.7203716693621E-12" izz="1.60467609944965E-06"/>
                </inertial>
            <visual>
                <origin xyz="0 0 0" rpy="0 0 0"/>
                <geometry>
                    <mesh filename="package://griphis_xacro_stl/meshes/nail1_1_link.STL"/>
                    </geometry>
                <material name="">
                    <color rgba="1 1 1 1"/>
                    </material>
                </visual>
            <collision>
                <origin xyz="0 0 0" rpy="0 0 0"/>
                <geometry>
                    <mesh filename="package://griphis_xacro_stl/meshes/nail1_1_link.STL"/>
                    </geometry>
                </collision>
            </link>
        <joint name="${prefix}nail1_rotate_1" type="continuous">
            <origin xyz="-0.00031819805152675075 -0.014681801948467067 -0.019699999999999995" rpy="1.5707963267948433 -1.5707963267948966 0.0"/>
            <parent link="${prefix}roll_1_link"/>
            <child link="${prefix}nail1_1_link"/>
            <axis xyz="0 -1 0"/>
            <mimic joint="${prefix}worm_rotate_1" multiplier="0.091" offset="0"/>
            </joint>
        <link name="${prefix}nail2_1_link">
            <inertial>
                <origin xyz="0.0375922338704431 -0.000920668174592305 -5.01249966510589E-05" rpy="0 0 0"/>
                <mass value="0.00783920613274618"/>
                <inertia ixx="3.26764420600123E-07" ixy="-3.04083796030301E-07" ixz="3.01596352148099E-10" iyy="1.60307023285989E-06" iyz="-3.50228545349602E-11" izz="1.7600802033745E-06"/>
                </inertial>
            <visual>
                <origin xyz="0 0 0" rpy="0 0 0"/>
                <geometry>
                    <mesh filename="package://griphis_xacro_stl/meshes/nail2_1_link.STL"/>
                    </geometry>
                <material name="">
                    <color rgba="0.752941176470588 0.752941176470588 0.752941176470588 1"/>
                    </material>
                </visual>
            <collision>
                <origin xyz="0 0 0" rpy="0 0 0"/>
                <geometry>
                    <mesh filename="package://griphis_xacro_stl/meshes/nail2_1_link.STL"/>
                    </geometry>
                </collision>
            </link>
        <joint name="${prefix}nail2_rotate_1" type="continuous">
            <origin xyz="-0.015318198051535455 0.00031819805152833 -0.019699999999999995" rpy="-1.5707963267948963 -1.5707963267948966 0.0"/>
            <parent link="${prefix}roll_1_link"/>
            <child link="${prefix}nail2_1_link"/>
            <axis xyz="0 0 -1"/>
            <mimic joint="${prefix}worm_rotate_1" multiplier="0.091" offset="0"/>
            </joint>
        <link name="${prefix}nail3_1_link">
            <inertial>
                <origin xyz="0.0376633576375596 -4.50239708446043E-05 0.000912382199221681" rpy="0 0 0"/>
                <mass value="0.00782164323980883"/>
                <inertia ixx="3.26387568167113E-07" ixy="1.94469452026803E-10" ixz="3.03929104031752E-07" iyy="1.75640452707706E-06" iyz="-1.77166863072923E-11" izz="1.59916689354216E-06"/>
                </inertial>
            <visual>
                <origin xyz="0 0 0" rpy="0 0 0"/>
                <geometry>
                    <mesh filename="package://griphis_xacro_stl/meshes/nail3_1_link.STL"/>
                    </geometry>
                <material name="">
                    <color rgba="0.752941176470588 0.752941176470588 0.752941176470588 1"/>
                    </material>
                </visual>
            <collision>
                <origin xyz="0 0 0" rpy="0 0 0"/>
                <geometry>
                    <mesh filename="package://griphis_xacro_stl/meshes/nail3_1_link.STL"/>
                    </geometry>
                </collision>
            </link>
        <joint name="${prefix}nail3_rotate_1" type="continuous">
            <origin xyz="-0.00031819805152675737 0.015318198051532934 -0.019700000000000092" rpy="-1.5707963267948963 -1.5707963267948966 0.0"/>
            <parent link="${prefix}roll_1_link"/>
            <child link="${prefix}nail3_1_link"/>
            <axis xyz="0 -1 0"/>
            <mimic joint="${prefix}worm_rotate_1" multiplier="0.091" offset="0"/>
            </joint>
        <link name="${prefix}nail4_1_link">
            <inertial>
                <origin xyz="0.0376199045292883 0.000916237603659741 4.27065705779009E-05" rpy="0 0 0"/>
                <mass value="0.00783130292561273"/>
                <inertia ixx="3.26490723468266E-07" ixy="3.0398859313737E-07" ixz="-4.37077734142467E-10" iyy="1.60061195688429E-06" iyz="2.94387193060157E-11" izz="1.75778452318195E-06"/>
                </inertial>
            <visual>
                <origin xyz="0 0 0" rpy="0 0 0"/>
                <geometry>
                    <mesh filename="package://griphis_xacro_stl/meshes/nail4_1_link.STL"/>
                    </geometry>
                <material name="">
                    <color rgba="0.752941176470588 0.752941176470588 0.752941176470588 1"/>
                    </material>
                </visual>
            <collision>
                <origin xyz="0 0 0" rpy="0 0 0"/>
                <geometry>
                    <mesh filename="package://griphis_xacro_stl/meshes/nail4_1_link.STL"/>
                    </geometry>
                </collision>
            </link>
        <joint name="${prefix}nail4_rotate_1" type="continuous">
            <origin xyz="0.014681801948464546 0.00031819805152833667 -0.019699999999999995" rpy="-1.5707963267948963 -1.5707963267948966 0.0"/>
            <parent link="${prefix}roll_1_link"/>
            <child link="${prefix}nail4_1_link"/>
            <axis xyz="0 0 1"/>
            <mimic joint="${prefix}worm_rotate_1" multiplier="0.091" offset="0"/>
            </joint>
        <link name="${prefix}nail-cp1">
            <inertial>
                <origin xyz="-2.058274506931E-05 -0.000405813357968389 -0.0658092329631552" rpy="0 0 0"/>
                <mass value="0.0011585387013778"/>
                <inertia ixx="1.05682260080874E-07" ixy="-1.5764583148915E-09" ixz="-7.53303890952621E-11" iyy="1.05682260080874E-07" iyz="7.53303890952626E-11" izz="2.1081276337663E-07"/>
                </inertial>
            <visual>
                <origin xyz="0 0 0" rpy="0 0 0"/>
                <geometry>
                    <mesh filename="package://griphis_xacro_stl/meshes/nail-cp1.STL"/>
                    </geometry>
                <material name="">
                    <color rgba="1 1 1 1"/>
                    </material>
                </visual>
            <collision>
                <origin xyz="0 0 0" rpy="0 0 0"/>
                <geometry>
                    <mesh filename="package://griphis_xacro_stl/meshes/nail-cp1.STL"/>
                    </geometry>
                </collision>
            </link>
        <joint name="${prefix}nail-cp1" type="fixed">
            <origin xyz="-0.000636396103034807 0.00020999999999474846 0.0650000000000001" rpy="6.4948046940571666e-15 3.774758283725532e-15 -3.141592653589793"/>
            <parent link="${prefix}roll_1_link"/>
            <child link="${prefix}nail-cp1"/>
            <axis xyz="0 0 0"/>
            </joint>
        <link name="${prefix}gripper-cp1">
            <inertial>
                <origin xyz="-0.000249014516100668 -0.00102239026541428 -0.0133818116212472" rpy="0 0 0"/>
                <mass value="0.0105278029927928"/>
                <inertia ixx="2.49426973639437E-06" ixy="-4.53009756265879E-08" ixz="6.75736959711176E-08" iyy="2.70040122944883E-06" iyz="-2.88247256637324E-07" izz="2.67368335360225E-06"/>
                </inertial>
            <visual>
                <origin xyz="0 0 0" rpy="0 0 0"/>
                <geometry>
                    <mesh filename="package://griphis_xacro_stl/meshes/gripper-cp1.STL"/>
                    </geometry>
                <material name="">
                    <color rgba="1 1 1 1"/>
                    </material>
                </visual>
            <collision>
                <origin xyz="0 0 0" rpy="0 0 0"/>
                <geometry>
                    <mesh filename="package://griphis_xacro_stl/meshes/gripper-cp1.STL"/>
                    </geometry>
                </collision>
            </link>
        <joint name="${prefix}gripper-cp1" type="fixed">
            <origin xyz="0 0 0" rpy="0 0 0"/>
            <parent link="${prefix}gripper-cp1"/>
            <child link="${prefix}roll_1_link"/>
            <axis xyz="-0.0 -0.0 -0.0"/>
            </joint>
        <link name="${prefix}nailring1-cp1">
            <inertial>
                <origin xyz="0.000495209639942942 -2.15213012098869E-07 -0.00500225533856013" rpy="0 0 0"/>
                <mass value="0.00888435164177016"/>
                <inertia ixx="1.85848970375133E-06" ixy="4.08320407087235E-11" ixz="9.14133574374128E-10" iyy="1.88948158451332E-06" iyz="-1.8157617423749E-12" izz="3.47494887160992E-06"/>
                </inertial>
            <visual>
                <origin xyz="0 0 0" rpy="0 0 0"/>
                <geometry>
                    <mesh filename="package://griphis_xacro_stl/meshes/nailring1-cp1.STL"/>
                    </geometry>
                <material name="">
                    <color rgba="1 1 1 1"/>
                    </material>
                </visual>
            <collision>
                <origin xyz="0 0 0" rpy="0 0 0"/>
                <geometry>
                    <mesh filename="package://griphis_xacro_stl/meshes/nailring1-cp1.STL"/>
                    </geometry>
                </collision>
            </link>
        <joint name="${prefix}nailring1-cp1" type="fixed">
            <origin xyz="-0.0003181980515267614 0.033318198051532834 -0.048100053496672186" rpy="1.5707963267948433 -1.5707963267948966 0.0"/>
            <parent link="${prefix}roll_1_link"/>
            <child link="${prefix}nailring1-cp1"/>
            <axis xyz="0 0 0"/>
            </joint>
        <link name="${prefix}nailring1-cp2">
            <inertial>
                <origin xyz="0.000495209639943192 -2.15213011856008E-07 -0.00500225533855998" rpy="0 0 0"/>
                <mass value="0.00888435164177017"/>
                <inertia ixx="1.85848970375133E-06" ixy="4.08320407083519E-11" ixz="9.1413357437371E-10" iyy="1.88948158451332E-06" iyz="-1.81576174254404E-12" izz="3.47494887160992E-06"/>
                </inertial>
            <visual>
                <origin xyz="0 0 0" rpy="0 0 0"/>
                <geometry>
                    <mesh filename="package://griphis_xacro_stl/meshes/nailring1-cp2.STL"/>
                    </geometry>
                <material name="">
                    <color rgba="1 1 1 1"/>
                    </material>
                </visual>
            <collision>
                <origin xyz="0 0 0" rpy="0 0 0"/>
                <geometry>
                    <mesh filename="package://griphis_xacro_stl/meshes/nailring1-cp2.STL"/>
                    </geometry>
                </collision>
            </link>
        <joint name="${prefix}nailring1-cp2" type="fixed">
            <origin xyz="0.03268180194846475 0.00031819805152834697 -0.048100053496672394" rpy="-5.645484080218921e-14 -1.5707963057214722 0.0"/>
            <parent link="${prefix}roll_1_link"/>
            <child link="${prefix}nailring1-cp2"/>
            <axis xyz="0 0 0"/>
            </joint>
        <link name="${prefix}nailring1-cp3">
            <inertial>
                <origin xyz="-0.000495209639943185 2.1521301184213E-07 -0.00500225533856018" rpy="0 0 0"/>
                <mass value="0.00888435164177015"/>
                <inertia ixx="1.85848970375133E-06" ixy="4.08320407089207E-11" ixz="-9.14133574373382E-10" iyy="1.88948158451332E-06" iyz="1.81576174213503E-12" izz="3.47494887160991E-06"/>
                </inertial>
            <visual>
                <origin xyz="0 0 0" rpy="0 0 0"/>
                <geometry>
                    <mesh filename="package://griphis_xacro_stl/meshes/nailring1-cp3.STL"/>
                    </geometry>
                <material name="">
                    <color rgba="1 1 1 1"/>
                    </material>
                </visual>
            <collision>
                <origin xyz="0 0 0" rpy="0 0 0"/>
                <geometry>
                    <mesh filename="package://griphis_xacro_stl/meshes/nailring1-cp3.STL"/>
                    </geometry>
                </collision>
            </link>
        <joint name="${prefix}nailring1-cp3" type="fixed">
            <origin xyz="-0.00031819805152674674 -0.03268180194846797 -0.0482999465033276" rpy="-1.5707963267948963 -1.5707963267948966 0.0"/>
            <parent link="${prefix}roll_1_link"/>
            <child link="${prefix}nailring1-cp3"/>
            <axis xyz="0 0 0"/>
            </joint>
        <link name="${prefix}nailring1-cp4">
            <inertial>
                <origin xyz="-0.000495209639943033 2.15213012022542E-07 -0.00500225533856014" rpy="0 0 0"/>
                <mass value="0.00888435164177017"/>
                <inertia ixx="1.85848970375133E-06" ixy="4.08320407090649E-11" ixz="-9.14133574373576E-10" iyy="1.88948158451332E-06" iyz="1.81576174274984E-12" izz="3.47494887160992E-06"/>
                </inertial>
            <visual>
                <origin xyz="0 0 0" rpy="0 0 0"/>
                <geometry>
                    <mesh filename="package://griphis_xacro_stl/meshes/nailring1-cp4.STL"/>
                    </geometry>
                <material name="">
                    <color rgba="1 1 1 1"/>
                    </material>
                </visual>
            <collision>
                <origin xyz="0 0 0" rpy="0 0 0"/>
                <geometry>
                    <mesh filename="package://griphis_xacro_stl/meshes/nailring1-cp4.STL"/>
                    </geometry>
                </collision>
            </link>
        <joint name="${prefix}nailring1-cp4" type="fixed">
            <origin xyz="-0.03331819805153535 0.00031819805152833233 -0.048099946503327794" rpy="3.14159265358973 -1.5707963057214722 0.0"/>
            <parent link="${prefix}roll_1_link"/>
            <child link="${prefix}nailring1-cp4"/>
            <axis xyz="0 0 0"/>
            </joint>
        <link name="${prefix}mid_pitch_2_link">
            <inertial>
                <origin xyz="-0.0327473641033502 -0.0322605669359661 0.000309352298986196" rpy="0 0 0"/>
                <mass value="0.0769502016363242"/>
                <inertia ixx="1.72130959551283E-05" ixy="1.01485711646082E-08" ixz="9.64338520342348E-08" iyy="1.36643051799986E-05" iyz="-5.60812725052765E-07" izz="1.63206675803235E-05"/>
                </inertial>
            <visual>
                <origin xyz="0 0 0" rpy="0 0 0"/>
                <geometry>
                    <mesh filename="package://griphis_xacro_stl/meshes/mid_pitch_2_link.STL"/>
                    </geometry>
                <material name="">
                    <color rgba="0.752941176470588 0.752941176470588 0.752941176470588 1"/>
                    </material>
                </visual>
            <collision>
                <origin xyz="0 0 0" rpy="0 0 0"/>
                <geometry>
                    <mesh filename="package://griphis_xacro_stl/meshes/mid_pitch_2_link.STL"/>
                    </geometry>
                </collision>
            </link>
        <joint name="${prefix}mid_pitch_2" type="continuous">
            <origin xyz="-0.029900000000000003 0.0352000000000001 0.0002100000000035008" rpy="0.0 0.0 0.0"/>
            <parent link="${prefix}base_link"/>
            <child link="${prefix}mid_pitch_2_link"/>
            <axis xyz="0 -1 0"/>
            <limit effort="3" velocity="10"/>
            <mimic joint="${prefix}mid_pitch_1" multiplier="1" offset="0"/>
            </joint>
        <link name="${prefix}pitch_2_link">
            <inertial>
                <origin xyz="-0.0191893034316743 0.0172315960705706 -0.00342856576323701" rpy="0 0 0"/>
                <mass value="0.0105178263834885"/>
                <inertia ixx="5.84801171286379E-07" ixy="3.57321505353334E-09" ixz="-8.81524447786701E-08" iyy="1.04603360596441E-06" iyz="1.51990880905164E-13" izz="9.82964870358905E-07"/>
                </inertial>
            <visual>
                <origin xyz="0 0 0" rpy="0 0 0"/>
                <geometry>
                    <mesh filename="package://griphis_xacro_stl/meshes/pitch_2_link.STL"/>
                    </geometry>
                <material name="">
                    <color rgba="0.298039215686275 0.298039215686275 0.298039215686275 1"/>
                    </material>
                </visual>
            <collision>
                <origin xyz="0 0 0" rpy="0 0 0"/>
                <geometry>
                    <mesh filename="package://griphis_xacro_stl/meshes/pitch_2_link.STL"/>
                    </geometry>
                </collision>
            </link>
        <joint name="${prefix}pitch_2" type="continuous">
            <origin xyz="-0.0640000000000067 -0.0350999999999972 0" rpy="0 0 0"/>
            <parent link="${prefix}mid_pitch_2_link"/>
            <child link="${prefix}pitch_2_link"/>
            <axis xyz="0 1 0"/>
            <limit effort="3" velocity="10"/>
            </joint>
        <link name="${prefix}yaw_2_link">
            <inertial>
                <origin xyz="-0.00934924449476787 -1.20738749553873E-09 -0.00656570463247875" rpy="0 0 0"/>
                <mass value="0.0544536529144548"/>
                <inertia ixx="6.1608306877813E-06" ixy="-1.48630786812854E-08" ixz="-3.66333645918454E-08" iyy="7.36783210634451E-06" iyz="1.48635489875795E-08" izz="7.24407314817233E-06"/>
                </inertial>
            <visual>
                <origin xyz="0 0 0" rpy="0 0 0"/>
                <geometry>
                    <mesh filename="package://griphis_xacro_stl/meshes/yaw_2_link.STL"/>
                    </geometry>
                <material name="">
                    <color rgba="0.180392156862745 0.180392156862745 0.180392156862745 1"/>
                    </material>
                </visual>
            <collision>
                <origin xyz="0 0 0" rpy="0 0 0"/>
                <geometry>
                    <mesh filename="package://griphis_xacro_stl/meshes/yaw_2_link.STL"/>
                    </geometry>
                </collision>
            </link>
        <joint name="${prefix}yaw_2" type="continuous">
            <origin xyz="-0.0419999999999942 0.0175000000000631 0.0174999999999867" rpy="0 0 0"/>
            <parent link="${prefix}pitch_2_link"/>
            <child link="${prefix}yaw_2_link"/>
            <axis xyz="0 0 -1"/>
            <limit effort="3" velocity="10"/>
            </joint>
        <link name="${prefix}roll_2_link">
            <inertial>
                <origin xyz="-0.0304847934275298 0.000533683595516123 -0.000138763582688578" rpy="0 0 0"/>
                <mass value="0.0617238803473503"/>
                <inertia ixx="1.72112591146286E-05" ixy="-2.34655399562003E-07" ixz="-1.72186999812873E-07" iyy="1.09105230206178E-05" iyz="-3.90599560037894E-08" izz="1.62402505711448E-05"/>
                </inertial>
            <visual>
                <origin xyz="0 0 0" rpy="0 0 0"/>
                <geometry>
                    <mesh filename="package://griphis_xacro_stl/meshes/roll_2_link.STL"/>
                    </geometry>
                <material name="">
                    <color rgba="1 1 1 1"/>
                    </material>
                </visual>
            <collision>
                <origin xyz="0 0 0" rpy="0 0 0"/>
                <geometry>
                    <mesh filename="package://griphis_xacro_stl/meshes/roll_2_link.STL"/>
                    </geometry>
                </collision>
            </link>
        <joint name="${prefix}roll_2" type="continuous">
            <origin xyz="-0.0280000000000042 0 -0.0175000000000007" rpy="0 0 0"/>
            <parent link="${prefix}yaw_2_link"/>
            <child link="${prefix}roll_2_link"/>
            <axis xyz="-1 0 0"/>
            <limit effort="3" velocity="10"/>
            </joint>
        <link name="${prefix}worm_2_link">
            <inertial>
                <origin xyz="-0.00680389920380498 5.66707617536341E-05 3.76180533663562E-06" rpy="0 0 0"/>
                <mass value="0.00387257616321651"/>
                <inertia ixx="2.0626455720602E-07" ixy="6.3200237698076E-10" ixz="-1.25909856906162E-09" iyy="1.713062458146E-07" iyz="1.39152999506885E-11" izz="1.71128105557195E-07"/>
                </inertial>
            <visual>
                <origin xyz="0 0 0" rpy="0 0 0"/>
                <geometry>
                    <mesh filename="package://griphis_xacro_stl/meshes/worm_2_link.STL"/>
                    </geometry>
                <material name="">
                    <color rgba="0.752941176470588 0.752941176470588 0.752941176470588 1"/>
                    </material>
                </visual>
            <collision>
                <origin xyz="0 0 0" rpy="0 0 0"/>
                <geometry>
                    <mesh filename="package://griphis_xacro_stl/meshes/worm_2_link.STL"/>
                    </geometry>
                </collision>
            </link>
        <joint name="${prefix}worm_rotate_2" type="continuous">
            <origin xyz="-0.0470000000000015 0 0" rpy="0 0 0"/>
            <parent link="${prefix}roll_2_link"/>
            <child link="${prefix}worm_2_link"/>
            <axis xyz="0.737216674660088 0 0.675656402769279"/>
            <limit effort="15" velocity="10"/>
            </joint>
        <link name="${prefix}nail1_2_link">
            <inertial>
                <origin xyz="-0.0375115559402153 0.000154761897861344 -0.000927613439127735" rpy="0 0 0"/>
                <mass value="0.00785451508753956"/>
                <inertia ixx="3.26792929870324E-07" ixy="-2.23311778394515E-10" ixz="3.04391588566463E-07" iyy="1.76174668735889E-06" iyz="8.72037168507631E-12" izz="1.60467609944963E-06"/>
                </inertial>
            <visual>
                <origin xyz="0 0 0" rpy="0 0 0"/>
                <geometry>
                    <mesh filename="package://griphis_xacro_stl/meshes/nail1_2_link.STL"/>
                    </geometry>
                <material name="">
                    <color rgba="1 1 1 1"/>
                    </material>
                </visual>
            <collision>
                <origin xyz="0 0 0" rpy="0 0 0"/>
                <geometry>
                    <mesh filename="package://griphis_xacro_stl/meshes/nail1_2_link.STL"/>
                    </geometry>
                </collision>
            </link>
        <joint name="${prefix}nail1_rotate_2" type="continuous">
            <origin xyz="-0.0570000000000014 0 -0.0149999999999872" rpy="0 0 0"/>
            <parent link="${prefix}roll_2_link"/>
            <child link="${prefix}nail1_2_link"/>
            <axis xyz="0 -1 0"/>
            <mimic joint="${prefix}worm_rotate_2" multiplier="0.091" offset="0"/>
            </joint>
        <link name="${prefix}nail2_2_link">
            <inertial>
                <origin xyz="-0.0375922338704413 0.000920668174601659 0.000149875003347476" rpy="0 0 0"/>
                <mass value="0.00783920613274653"/>
                <inertia ixx="3.26764420600132E-07" ixy="-3.0408379603033E-07" ixz="-3.01596352109658E-10" iyy="1.60307023286001E-06" iyz="3.50228545423785E-11" izz="1.76008020337463E-06"/>
                </inertial>
            <visual>
                <origin xyz="0 0 0" rpy="0 0 0"/>
                <geometry>
                    <mesh filename="package://griphis_xacro_stl/meshes/nail2_2_link.STL"/>
                    </geometry>
                <material name="">
                    <color rgba="0.752941176470588 0.752941176470588 0.752941176470588 1"/>
                    </material>
                </visual>
            <collision>
                <origin xyz="0 0 0" rpy="0 0 0"/>
                <geometry>
                    <mesh filename="package://griphis_xacro_stl/meshes/nail2_2_link.STL"/>
                    </geometry>
                </collision>
            </link>
        <joint name="${prefix}nail2_rotate_2" type="continuous">
            <origin xyz="-0.0570000000000009 0.015 0" rpy="0 0 0"/>
            <parent link="${prefix}roll_2_link"/>
            <child link="${prefix}nail2_2_link"/>
            <axis xyz="0 0 -1"/>
            <mimic joint="${prefix}worm_rotate_2" multiplier="0.091" offset="0"/>
            </joint>
        <link name="${prefix}nail3_2_link">
            <inertial>
                <origin xyz="-0.0376633576375554 4.50239708458949E-05 0.000912382199144402" rpy="0 0 0"/>
                <mass value="0.00782164323980893"/>
                <inertia ixx="3.26387568167086E-07" ixy="1.94469452048084E-10" ixz="-3.03929104031706E-07" iyy="1.75640452707709E-06" iyz="1.77166863189614E-11" izz="1.59916689354222E-06"/>
                </inertial>
            <visual>
                <origin xyz="0 0 0" rpy="0 0 0"/>
                <geometry>
                    <mesh filename="package://griphis_xacro_stl/meshes/nail3_2_link.STL"/>
                    </geometry>
                <material name="">
                    <color rgba="0.752941176470588 0.752941176470588 0.752941176470588 1"/>
                    </material>
                </visual>
            <collision>
                <origin xyz="0 0 0" rpy="0 0 0"/>
                <geometry>
                    <mesh filename="package://griphis_xacro_stl/meshes/nail3_2_link.STL"/>
                    </geometry>
                </collision>
            </link>
        <joint name="${prefix}nail3_rotate_2" type="continuous">
            <origin xyz="-0.0570000000000004 0 0.0150000000000128" rpy="0 0 0"/>
            <parent link="${prefix}roll_2_link"/>
            <child link="${prefix}nail3_2_link"/>
            <axis xyz="0 1 0"/>
            <mimic joint="${prefix}worm_rotate_2" multiplier="0.091" offset="0"/>
            </joint>
        <link name="${prefix}nail4_2_link">
            <inertial>
                <origin xyz="-0.0376199045292857 -0.000916237603655147 -0.000157293429422369" rpy="0 0 0"/>
                <mass value="0.00783130292561298"/>
                <inertia ixx="3.26490723468276E-07" ixy="3.03988593137378E-07" ixz="4.37077734057104E-10" iyy="1.60061195688436E-06" iyz="-2.94387192594929E-11" izz="1.75778452318202E-06"/>
                </inertial>
            <visual>
                <origin xyz="0 0 0" rpy="0 0 0"/>
                <geometry>
                    <mesh filename="package://griphis_xacro_stl/meshes/nail4_2_link.STL"/>
                    </geometry>
                <material name="">
                    <color rgba="0.752941176470588 0.752941176470588 0.752941176470588 1"/>
                    </material>
                </visual>
            <collision>
                <origin xyz="0 0 0" rpy="0 0 0"/>
                <geometry>
                    <mesh filename="package://griphis_xacro_stl/meshes/nail4_2_link.STL"/>
                    </geometry>
                </collision>
            </link>
        <joint name="${prefix}nail4_rotate_2" type="continuous">
            <origin xyz="-0.0570000000000017 -0.0149999999999955 0" rpy="0 0 0"/>
            <parent link="${prefix}roll_2_link"/>
            <child link="${prefix}nail4_2_link"/>
            <axis xyz="0 0 1"/>
            <mimic joint="${prefix}worm_rotate_2" multiplier="0.091" offset="0"/>
            </joint>
        <link name="${prefix}nail-cp2">
            <inertial>
                <origin xyz="0.000615813357965365 -0.00061581335794697 -0.0658092329631574" rpy="0 0 0"/>
                <mass value="0.00115853870137781"/>
                <inertia ixx="1.05682260080874E-07" ixy="-1.5764583148907E-09" ixz="-7.53303890952508E-11" iyy="1.05682260080874E-07" iyz="7.53303890920378E-11" izz="2.10812763376632E-07"/>
                </inertial>
            <visual>
                <origin xyz="0 0 0" rpy="0 0 0"/>
                <geometry>
                    <mesh filename="package://griphis_xacro_stl/meshes/nail-cp2.STL"/>
                    </geometry>
                <material name="">
                    <color rgba="0.796078431372549 0.823529411764706 0.937254901960784 1"/>
                    </material>
                </visual>
            <collision>
                <origin xyz="0 0 0" rpy="0 0 0"/>
                <geometry>
                    <mesh filename="package://griphis_xacro_stl/meshes/nail-cp2.STL"/>
                    </geometry>
                </collision>
            </link>
        <joint name="${prefix}nail-cp2" type="fixed">
            <origin xyz="-0.141700000000001 -0.000318198051535531 -0.00031819805151536" rpy="-1.5707963267949 0 1.5707963267949"/>
            <parent link="${prefix}roll_2_link"/>
            <child link="${prefix}nail-cp2"/>
            <axis xyz="0 0 0"/>
            </joint>
        <link name="${prefix}gripper-cp2">
            <inertial>
                <origin xyz="0.000249014516096963 -0.00102239026539895 0.0133818116212488" rpy="0 0 0"/>
                <mass value="0.0105278029927927"/>
                <inertia ixx="2.49426973639434E-06" ixy="4.53009756265701E-08" ixz="6.75736959710746E-08" iyy="2.70040122944888E-06" iyz="2.88247256637327E-07" izz="2.67368335360219E-06"/>
                </inertial>
            <visual>
                <origin xyz="0 0 0" rpy="0 0 0"/>
                <geometry>
                    <mesh filename="package://griphis_xacro_stl/meshes/gripper-cp2.STL"/>
                    </geometry>
                <material name="">
                    <color rgba="1 1 1 1"/>
                    </material>
                </visual>
            <collision>
                <origin xyz="0 0 0" rpy="0 0 0"/>
                <geometry>
                    <mesh filename="package://griphis_xacro_stl/meshes/gripper-cp2.STL"/>
                    </geometry>
                </collision>
            </link>
        <joint name="${prefix}gripper-cp2" type="fixed">
            <origin xyz="-0.0766999999999999 -0.000318198051539618 -0.000318198051517046" rpy="-1.57079632679485 0 -1.57079632679489"/>
            <parent link="${prefix}roll_2_link"/>
            <child link="${prefix}gripper-cp2"/>
            <axis xyz="0 0 0"/>
            </joint>
        <link name="${prefix}nailring2-cp1">
            <inertial>
                <origin xyz="0.000495209639943872 -2.15213011231508E-07 -0.0050022553385601" rpy="0 0 0"/>
                <mass value="0.00888435164177013"/>
                <inertia ixx="1.85848970375132E-06" ixy="4.08320407075244E-11" ixz="9.14133574374455E-10" iyy="1.88948158451332E-06" iyz="-1.81576174187697E-12" izz="3.47494887160991E-06"/>
                </inertial>
            <visual>
                <origin xyz="0 0 0" rpy="0 0 0"/>
                <geometry>
                    <mesh filename="package://griphis_xacro_stl/meshes/nailring2-cp1.STL"/>
                    </geometry>
                <material name="">
                    <color rgba="1 1 1 1"/>
                    </material>
                </visual>
            <collision>
                <origin xyz="0 0 0" rpy="0 0 0"/>
                <geometry>
                    <mesh filename="package://griphis_xacro_stl/meshes/nailring2-cp1.STL"/>
                    </geometry>
                </collision>
            </link>
        <joint name="${prefix}nailring2-cp1" type="fixed">
            <origin xyz="-0.0285999465033246 0 0.0330000000000001" rpy="3.14159265358978 0 -3.14159238847494"/>
            <parent link="${prefix}roll_2_link"/>
            <child link="${prefix}nailring2-cp1"/>
            <axis xyz="0 0 0"/>
            </joint>
        <link name="${prefix}nailring2-cp2">
            <inertial>
                <origin xyz="0.000495209639942984 -2.15213012050297E-07 -0.00500225533856015" rpy="0 0 0"/>
                <mass value="0.00888435164177019"/>
                <inertia ixx="1.85848970375134E-06" ixy="4.08320407074391E-11" ixz="9.14133574373919E-10" iyy="1.88948158451332E-06" iyz="-1.81576174216739E-12" izz="3.47494887160993E-06"/>
                </inertial>
            <visual>
                <origin xyz="0 0 0" rpy="0 0 0"/>
                <geometry>
                    <mesh filename="package://griphis_xacro_stl/meshes/nailring2-cp2.STL"/>
                    </geometry>
                <material name="">
                    <color rgba="1 1 1 1"/>
                    </material>
                </visual>
            <collision>
                <origin xyz="0 0 0" rpy="0 0 0"/>
                <geometry>
                    <mesh filename="package://griphis_xacro_stl/meshes/nailring2-cp2.STL"/>
                    </geometry>
                </collision>
            </link>
        <joint name="${prefix}nailring2-cp2" type="fixed">
            <origin xyz="-0.0285999465033264 -0.0330000000000002 0" rpy="1.57079632679488 0 3.14159265358979"/>
            <parent link="${prefix}roll_2_link"/>
            <child link="${prefix}nailring2-cp2"/>
            <axis xyz="0 0 0"/>
            </joint>
        <link name="${prefix}nailring2-cp3">
            <inertial>
                <origin xyz="-0.000495209639942817 2.15213012078053E-07 -0.00500225533856008" rpy="0 0 0"/>
                <mass value="0.00888435164177013"/>
                <inertia ixx="1.85848970375132E-06" ixy="4.08320407098813E-11" ixz="-9.14133574373917E-10" iyy="1.88948158451331E-06" iyz="1.81576173997682E-12" izz="3.4749488716099E-06"/>
                </inertial>
            <visual>
                <origin xyz="0 0 0" rpy="0 0 0"/>
                <geometry>
                    <mesh filename="package://griphis_xacro_stl/meshes/nailring2-cp3.STL"/>
                    </geometry>
                <material name="">
                    <color rgba="1 1 1 1"/>
                    </material>
                </visual>
            <collision>
                <origin xyz="0 0 0" rpy="0 0 0"/>
                <geometry>
                    <mesh filename="package://griphis_xacro_stl/meshes/nailring2-cp3.STL"/>
                    </geometry>
                </collision>
            </link>
        <joint name="${prefix}nailring2-cp3" type="fixed">
            <origin xyz="-0.0284000534966716 0 -0.0330000000000008" rpy="0 0 3.14159238847493"/>
            <parent link="${prefix}roll_2_link"/>
            <child link="${prefix}nailring2-cp3"/>
            <axis xyz="0 0 0"/>
            </joint>
        <link name="${prefix}nailring2-cp4">
            <inertial>
                <origin xyz="-0.000495209639943039 2.15213012015603E-07 -0.00500225533856" rpy="0 0 0"/>
                <mass value="0.00888435164177014"/>
                <inertia ixx="1.85848970375133E-06" ixy="4.08320407107192E-11" ixz="-9.14133574373996E-10" iyy="1.88948158451331E-06" iyz="1.81576174170535E-12" izz="3.47494887160991E-06"/>
                </inertial>
            <visual>
                <origin xyz="0 0 0" rpy="0 0 0"/>
                <geometry>
                    <mesh filename="package://griphis_xacro_stl/meshes/nailring2-cp4.STL"/>
                    </geometry>
                <material name="">
                    <color rgba="1 1 1 1"/>
                    </material>
                </visual>
            <collision>
                <origin xyz="0 0 0" rpy="0 0 0"/>
                <geometry>
                    <mesh filename="package://griphis_xacro_stl/meshes/nailring2-cp4.STL"/>
                    </geometry>
                </collision>
            </link>
        <joint name="${prefix}nailring2-cp4" type="fixed">
            <origin xyz="-0.0286000534966706 0.0329999999999998 0" rpy="-1.57079632679492 0 3.14159265358979"/>
            <parent link="${prefix}roll_2_link"/>
            <child link="${prefix}nailring2-cp4"/>
            <axis xyz="0 0 0"/>
            </joint>
        </xacro:macro>
    </robot>
